#VRML_SIM R2025a utf8

EXTERNPROTO "https://raw.githubusercontent.com/cyberbotics/webots/R2025a/projects/objects/backgrounds/protos/TexturedBackground.proto"
EXTERNPROTO "https://raw.githubusercontent.com/cyberbotics/webots/R2025a/projects/objects/backgrounds/protos/TexturedBackgroundLight.proto"
EXTERNPROTO "https://raw.githubusercontent.com/cyberbotics/webots/R2025a/projects/objects/factory/containers/protos/WoodenBox.proto"

WorldInfo {
}
Viewpoint {
  orientation -0.4305552228486469 -0.3360403237803339 0.8376748180955186 4.2996684917366474
  position 3.299898507631116 5.10840839629307 3.409559010043468
}
TexturedBackground {
}
TexturedBackgroundLight {
}
Robot {
  translation 3.661770011121687 -0.11957699974002758 0.03971909827464204
  rotation 1.3835569179542944e-07 -3.994136240479347e-08 0.9999999999999897 -3.123730581148788
  children [
    DEF compass Compass {
    }
    DEF BODY Shape {
      appearance PBRAppearance {
        baseColor 0.917647 0.145098 0.145098
        roughness 1
        metalness 0
      }
      geometry Box {
        size 0.2 0.1 0.05
      }
    }
    DEF WHEEL1 HingeJoint {
      jointParameters HingeJointParameters {
        position 69.06016951679311
        axis 0 1 0
        anchor 0.05 0.06 0
      }
      device [
        PositionSensor {
          name "encoder1"
        }
        RotationalMotor {
          name "wheel1"
        }
      ]
      endPoint Solid {
        translation 0.05000344272327369 0.060000001823789756 1.8829861826205834e-06
        rotation -0.3574861709120364 0.6603805766510332 -0.6603795360159935 3.8282536916806085
        children [
          DEF WHEEL Shape {
            appearance PBRAppearance {
              baseColor 0.305882 0.898039 0.25098
              roughness 1
              metalness 0
            }
            geometry Cylinder {
              height 0.02
              radius 0.04
              subdivision 24
            }
          }
        ]
        boundingObject USE WHEEL
        physics Physics {
        }
      }
    }
    DEF WHEEL2 HingeJoint {
      jointParameters HingeJointParameters {
        position 200.52494543024224
        axis 0 1 0
        anchor 0.05 -0.06 0
      }
      device [
        PositionSensor {
          name "encoder2"
        }
        RotationalMotor {
          name "wheel2"
        }
      ]
      endPoint Solid {
        translation 0.05000344477271748 -0.059999998174488686 1.8791262067064417e-06
        rotation 0.7661002280231883 0.45447162906880345 -0.45447329843937656 1.834144445141554
        children [
          USE WHEEL
        ]
        name "solid(1)"
        boundingObject USE WHEEL
        physics Physics {
        }
      }
    }
    DEF WHEEL3 HingeJoint {
      jointParameters HingeJointParameters {
        position 69.06019884767103
        axis 0 1 0
        anchor -0.05 0.06 0
      }
      device [
        RotationalMotor {
          name "wheel3"
        }
      ]
      endPoint Solid {
        translation -0.049996557293120344 0.05999999817434007 1.883016589705832e-06
        rotation 0.999248629897605 -0.027405931712784812 0.027406031356498634 1.5715516586737004
        children [
          USE WHEEL
        ]
        name "solid(2)"
        boundingObject USE WHEEL
        physics Physics {
        }
      }
    }
    DEF WHEEL4 HingeJoint {
      jointParameters HingeJointParameters {
        position 200.52497523687666
        axis 0 1 0
        anchor -0.05 -0.06 0
      }
      device [
        RotationalMotor {
          name "wheel4"
        }
      ]
      endPoint Solid {
        translation -0.04999655524367592 -0.060000001823938484 1.8791566126064416e-06
        rotation 0.9319454398577005 -0.2563954127843032 0.2563963522197687 1.641222722730143
        children [
          USE WHEEL
        ]
        name "solid(3)"
        boundingObject USE WHEEL
        physics Physics {
        }
      }
    }
    DEF DS_RIGHT DistanceSensor {
      translation 0.1 -0.03 0
      rotation 0 0 1 -0.3
      children [
        Shape {
          appearance PBRAppearance {
            baseColor 0.184314 0.596078 0.847059
            roughness 1
            metalness 0
          }
          geometry Box {
            size 0.01 0.01 0.01
          }
        }
      ]
      name "ds_right"
    }
    DEF DS_LEFT DistanceSensor {
      translation 0.1 0.03 0
      rotation 0 0 1 0.3
      children [
        Shape {
          appearance PBRAppearance {
            baseColor 0.184314 0.596078 0.847059
            roughness 1
            metalness 0
          }
          geometry Box {
            size 0.01 0.01 0.01
          }
        }
      ]
      name "ds_left"
    }
  ]
  boundingObject USE BODY
  physics Physics {
    density -1
    mass 1
  }
  controller "robotcar"
}
Robot {
  translation 2.675772104103019 2.8959674322860476 0.03972091246710382
  rotation -0.012358795377560478 -4.8240681957008915e-05 0.9999236260083328 -0.005015307179585982
  children [
    HingeJoint {
      jointParameters HingeJointParameters {
        position 86.33983999999921
        axis 0 0 1
        anchor 0 0.00280235 0.070858
      }
      device [
        RotationalMotor {
          name "lidarMotor"
        }
      ]
      endPoint Lidar {
        translation 4.1088968130543805e-19 0.0028023499999999995 0.070858
        rotation -1.7328999964244433e-06 -6.421579986750125e-05 -0.999999997936664 0.05395800000000665
        children [
          Compass {
            name "lidarCompass"
          }
          Shape {
            appearance PBRAppearance {
              metalness 0
            }
            geometry Cylinder {
              height 0.1
              radius 0.05
            }
          }
        ]
        horizontalResolution 1
        fieldOfView 0.1
        numberOfLayers 1
        maxRange 4
      }
    }
    DEF compass Compass {
    }
    DEF BODY Shape {
      appearance PBRAppearance {
        baseColor 0 0.145098 0.145098
        roughness 1
        metalness 0
      }
      geometry Box {
        size 0.2 0.1 0.05
      }
    }
    DEF WHEEL1 HingeJoint {
      jointParameters HingeJointParameters {
        position 55.32884177196838
        axis 0 1 0
        anchor 0.05 0.06 0
      }
      device [
        PositionSensor {
          name "encoder1"
        }
        RotationalMotor {
          name "wheel1"
        }
      ]
      endPoint Solid {
        translation 0.04999962911859798 0.060000001823789756 3.9064597129440455e-06
        rotation 0.061070038550005534 0.7057879890576004 -0.7057859200164943 3.019606782759325
        children [
          DEF WHEEL Shape {
            appearance PBRAppearance {
              baseColor 0.305882 0.898039 0.25098
              roughness 1
              metalness 0
            }
            geometry Cylinder {
              height 0.02
              radius 0.04
              subdivision 24
            }
          }
        ]
        boundingObject USE WHEEL
        physics Physics {
        }
      }
    }
    DEF WHEEL2 HingeJoint {
      jointParameters HingeJointParameters {
        position 190.30715999262654
        axis 0 1 0
        anchor 0.05 -0.06 0
      }
      device [
        PositionSensor {
          name "encoder2"
        }
        RotationalMotor {
          name "wheel2"
        }
      ]
      endPoint Solid {
        translation 0.049998921598264884 -0.059999998174488686 -3.7728800767461755e-06
        rotation -0.09839044707922827 0.7036745278456407 -0.7036771125912539 3.3377415038761815
        children [
          USE WHEEL
        ]
        name "solid(1)"
        boundingObject USE WHEEL
        physics Physics {
        }
      }
    }
    DEF WHEEL3 HingeJoint {
      jointParameters HingeJointParameters {
        position 55.32891780869917
        axis 0 1 0
        anchor -0.05 0.06 0
      }
      device [
        RotationalMotor {
          name "wheel3"
        }
      ]
      endPoint Solid {
        translation -0.050000399999999154 0.06 3.906470000088082e-06
        rotation 0.7113067474652218 -0.4970115160016922 0.4970133438572317 1.9050478376607471
        children [
          USE WHEEL
        ]
        name "solid(2)"
        boundingObject USE WHEEL
        physics Physics {
        }
      }
    }
    DEF WHEEL4 HingeJoint {
      jointParameters HingeJointParameters {
        position 190.30723673690835
        axis 0 1 0
        anchor -0.05 -0.06 0
      }
      device [
        RotationalMotor {
          name "wheel4"
        }
      ]
      endPoint Solid {
        translation -0.05000107854565794 -0.060000001823938484 -3.7728391127588544e-06
        rotation 0.48488976621368296 0.6184169706286116 -0.6184192469997766 2.2386225073555144
        children [
          USE WHEEL
        ]
        name "solid(3)"
        boundingObject USE WHEEL
        physics Physics {
        }
      }
    }
  ]
  name "Lidar Scanner"
  boundingObject USE BODY
  physics Physics {
    density -1
    mass 1
  }
  controller "slam"
}
Solid {
  translation 3.3 0.05 0
  children [
    DEF WALL Shape {
      appearance PBRAppearance {
      }
      geometry Box {
        size 0.5 0.1 0.1
      }
    }
  ]
  name "wall"
  boundingObject USE WALL
}
Solid {
  translation 3.1 0.25 0
  rotation 0 0 1 -1.5707953071795862
  children [
    DEF WALL Shape {
      appearance PBRAppearance {
      }
      geometry Box {
        size 0.5 0.1 0.1
      }
    }
  ]
  name "wall(1)"
  boundingObject USE WALL
}
Solid {
  translation 2.25 0.5 0
  rotation 0 0 1 -1.5707953071795862
  children [
    DEF WALL Shape {
      appearance PBRAppearance {
      }
      geometry Box {
        size 0.5 0.1 0.1
      }
    }
  ]
  name "wall(7)"
  boundingObject USE WALL
}
Solid {
  translation 2.25 1 0
  rotation 0 0 1 -1.5707953071795862
  children [
    DEF WALL Shape {
      appearance PBRAppearance {
      }
      geometry Box {
        size 0.5 0.1 0.1
      }
    }
  ]
  name "wall(10)"
  boundingObject USE WALL
}
Solid {
  translation 2.59 0.75 0
  rotation 0 0 1 -1.5707953071795862
  children [
    DEF WALL Shape {
      appearance PBRAppearance {
      }
      geometry Box {
        size 0.5 0.1 0.1
      }
    }
  ]
  name "wall(8)"
  boundingObject USE WALL
}
Solid {
  translation 3.3 -0.3 0
  rotation 0 0 1 3.14159
  children [
    DEF WALL Shape {
      appearance PBRAppearance {
      }
      geometry Box {
        size 0.5 0.1 0.1
      }
    }
  ]
  name "wall(2)"
  boundingObject USE WALL
}
Solid {
  translation 2.8 0.55 0
  rotation 0 0 1 3.14159
  children [
    DEF WALL Shape {
      appearance PBRAppearance {
      }
      geometry Box {
        size 0.5 0.1 0.1
      }
    }
  ]
  name "wall(3)"
  boundingObject USE WALL
}
Solid {
  translation 2.8 0.95 0
  rotation 0 0 1 3.14159
  children [
    DEF WALL Shape {
      appearance PBRAppearance {
      }
      geometry Box {
        size 0.5 0.1 0.4
      }
    }
  ]
  name "wall(9)"
  boundingObject USE WALL
}
Solid {
  translation 3.3 0.95 0
  rotation 0 0 1 3.14159
  children [
    DEF WALL Shape {
      appearance PBRAppearance {
      }
      geometry Box {
        size 0.5 0.1 0.1
      }
    }
  ]
  name "wall(13)"
  boundingObject USE WALL
}
Solid {
  translation 2.8 -0.3 0
  rotation 0 0 1 3.14159
  children [
    DEF WALL Shape {
      appearance PBRAppearance {
      }
      geometry Box {
        size 0.5 0.1 0.1
      }
    }
  ]
  name "wall(4)"
  boundingObject USE WALL
}
Solid {
  translation 2.75 -5.0981e-08 0
  rotation 0 0 1 -1.5707953071795862
  children [
    DEF WALL Shape {
      appearance PBRAppearance {
      }
      geometry Box {
        size 0.5 0.1 0.1
      }
    }
  ]
  name "wall(5)"
  boundingObject USE WALL
}
Solid {
  translation 3.55 0 0
  children [
    Solid {
      children [
        Shape {
          appearance PBRAppearance {
            baseColorMap ImageTexture {
              url [
                "https://raw.githubusercontent.com/cyberbotics/webots/R2025a/projects/appearances/protos/textures/parquetry/chequered_parquetry_base_color.jpg"
              ]
            }
            roughness 1
            roughnessMap ImageTexture {
              url [
                "https://raw.githubusercontent.com/cyberbotics/webots/R2025a/projects/appearances/protos/textures/parquetry/chequered_parquetry_roughness.jpg"
              ]
            }
            metalness 0
            normalMap ImageTexture {
              url [
                "https://raw.githubusercontent.com/cyberbotics/webots/R2025a/projects/appearances/protos/textures/parquetry/chequered_parquetry_normal.jpg"
              ]
            }
            occlusionMap ImageTexture {
              url [
                "https://raw.githubusercontent.com/cyberbotics/webots/R2025a/projects/appearances/protos/textures/parquetry/chequered_parquetry_occlusion.jpg"
              ]
            }
          }
          geometry IndexedFaceSet {
            coord Coordinate {
              point [
                -5 -5 0
                5 -5 0
                -5 5 0
                5 5 0
              ]
            }
            texCoord TextureCoordinate {
              point [
                0 0
                20 0
                0 20
                20 20
              ]
            }
            coordIndex [
              2, 0, 1, 3, -1
            ]
            texCoordIndex [
              2, 0, 1, 3, -1
            ]
          }
        }
      ]
      name "floor"
      model "floor"
      boundingObject Plane {
        size 10 10
      }
      locked TRUE
    }
    WoodenBox {
      translation -1.25 3 0.2
      size 0.1 0.1 0.3
    }
    Solid {
      translation 5.005 0 0.05
      children [
        Shape {
          appearance PBRAppearance {
            baseColorMap ImageTexture {
              url [
                "https://raw.githubusercontent.com/cyberbotics/webots/R2025a/projects/appearances/protos/textures/brushed_aluminium/brushed_aluminium_base_color.jpg"
              ]
            }
            roughnessMap ImageTexture {
              url [
                "https://raw.githubusercontent.com/cyberbotics/webots/R2025a/projects/appearances/protos/textures/brushed_aluminium/brushed_aluminium_roughness.jpg"
              ]
            }
            normalMap ImageTexture {
              url [
                "https://raw.githubusercontent.com/cyberbotics/webots/R2025a/projects/appearances/protos/textures/brushed_aluminium/brushed_aluminium_normal.jpg"
              ]
            }
          }
          geometry IndexedFaceSet {
            coord Coordinate {
              point [
                -0.005 5 0.05
                0.005 5 0.05
                0.005 5 -0.05
                -0.005 5 -0.05
                -0.005 -5 -0.05
                0.005 -5 -0.05
                0.005 -5 0.05
                -0.005 -5 0.05
                -0.005 -5 0.05
                0.005 -5 0.05
                0.005 5 0.05
                -0.005 5 0.05
                0.005 -5 -0.05
                -0.005 -5 -0.05
                -0.005 5 -0.05
                0.005 5 -0.05
                -0.005 -5 -0.05
                -0.005 -5 0.05
                -0.005 5 0.05
                -0.005 5 -0.05
                0.005 -5 0.05
                0.005 -5 -0.05
                0.005 5 -0.05
                0.005 5 0.05
              ]
            }
            texCoord TextureCoordinate {
              point [
                0.001 0.01
                0 0.01
                0 0
                0.001 0
                0 0
                0.001 0
                0.001 0.01
                0 0.01
                0 0.001
                0 0
                1 0
                1 0.001
                0 0.001
                0 0
                1 0
                1 0.001
                1 0
                1 0.01
                0 0.01
                0 0
                0 0.01
                0 0
                1 0
                1 0.01
              ]
            }
            coordIndex [
              0, 1, 2, 3, -1, 4, 5, 6, 7, -1, 8, 9, 10, 11, -1, 12, 13, 14, 15, -1, 16, 17, 18, 19, -1, 20, 21, 22, 23, -1
            ]
            creaseAngle 1.5
          }
        }
      ]
      name "wall"
      model "box"
      boundingObject Box {
        size 0.01 10 0.1
      }
    }
    Solid {
      translation -5.005 0 0.05
      children [
        Shape {
          appearance PBRAppearance {
            baseColorMap ImageTexture {
              url [
                "https://raw.githubusercontent.com/cyberbotics/webots/R2025a/projects/appearances/protos/textures/brushed_aluminium/brushed_aluminium_base_color.jpg"
              ]
            }
            roughnessMap ImageTexture {
              url [
                "https://raw.githubusercontent.com/cyberbotics/webots/R2025a/projects/appearances/protos/textures/brushed_aluminium/brushed_aluminium_roughness.jpg"
              ]
            }
            normalMap ImageTexture {
              url [
                "https://raw.githubusercontent.com/cyberbotics/webots/R2025a/projects/appearances/protos/textures/brushed_aluminium/brushed_aluminium_normal.jpg"
              ]
            }
          }
          geometry IndexedFaceSet {
            coord Coordinate {
              point [
                -0.005 5 0.05
                0.005 5 0.05
                0.005 5 -0.05
                -0.005 5 -0.05
                -0.005 -5 -0.05
                0.005 -5 -0.05
                0.005 -5 0.05
                -0.005 -5 0.05
                -0.005 -5 0.05
                0.005 -5 0.05
                0.005 5 0.05
                -0.005 5 0.05
                0.005 -5 -0.05
                -0.005 -5 -0.05
                -0.005 5 -0.05
                0.005 5 -0.05
                -0.005 -5 -0.05
                -0.005 -5 0.05
                -0.005 5 0.05
                -0.005 5 -0.05
                0.005 -5 0.05
                0.005 -5 -0.05
                0.005 5 -0.05
                0.005 5 0.05
              ]
            }
            texCoord TextureCoordinate {
              point [
                0.001 0.01
                0 0.01
                0 0
                0.001 0
                0 0
                0.001 0
                0.001 0.01
                0 0.01
                0 0.001
                0 0
                1 0
                1 0.001
                0 0.001
                0 0
                1 0
                1 0.001
                1 0
                1 0.01
                0 0.01
                0 0
                0 0.01
                0 0
                1 0
                1 0.01
              ]
            }
            coordIndex [
              0, 1, 2, 3, -1, 4, 5, 6, 7, -1, 8, 9, 10, 11, -1, 12, 13, 14, 15, -1, 16, 17, 18, 19, -1, 20, 21, 22, 23, -1
            ]
            creaseAngle 1.5
          }
        }
      ]
      name "wall#2"
      model "box"
      boundingObject Box {
        size 0.01 10 0.1
      }
    }
    Solid {
      translation 0 5.005 0.05
      children [
        Shape {
          appearance PBRAppearance {
            baseColorMap ImageTexture {
              url [
                "https://raw.githubusercontent.com/cyberbotics/webots/R2025a/projects/appearances/protos/textures/brushed_aluminium/brushed_aluminium_base_color.jpg"
              ]
            }
            roughnessMap ImageTexture {
              url [
                "https://raw.githubusercontent.com/cyberbotics/webots/R2025a/projects/appearances/protos/textures/brushed_aluminium/brushed_aluminium_roughness.jpg"
              ]
            }
            normalMap ImageTexture {
              url [
                "https://raw.githubusercontent.com/cyberbotics/webots/R2025a/projects/appearances/protos/textures/brushed_aluminium/brushed_aluminium_normal.jpg"
              ]
            }
          }
          geometry IndexedFaceSet {
            coord Coordinate {
              point [
                -5.01 0.005 0.05
                5.01 0.005 0.05
                5.01 0.005 -0.05
                -5.01 0.005 -0.05
                -5.01 -0.005 -0.05
                5.01 -0.005 -0.05
                5.01 -0.005 0.05
                -5.01 -0.005 0.05
                -5.01 -0.005 0.05
                5.01 -0.005 0.05
                5.01 0.005 0.05
                -5.01 0.005 0.05
                5.01 -0.005 -0.05
                -5.01 -0.005 -0.05
                -5.01 0.005 -0.05
                5.01 0.005 -0.05
                -5.01 -0.005 -0.05
                -5.01 -0.005 0.05
                -5.01 0.005 0.05
                -5.01 0.005 -0.05
                5.01 -0.005 0.05
                5.01 -0.005 -0.05
                5.01 0.005 -0.05
                5.01 0.005 0.05
              ]
            }
            texCoord TextureCoordinate {
              point [
                1 0.009980039920159682
                0 0.009980039920159682
                0 0
                1 0
                0 0
                1 0
                1 0.009980039920159682
                0 0.009980039920159682
                0 1
                0 0
                0.0009980039920159682 0
                0.0009980039920159682 1
                0 1
                0 0
                0.0009980039920159682 0
                0.0009980039920159682 1
                0.0009980039920159682 0
                0.0009980039920159682 0.009980039920159682
                0 0.009980039920159682
                0 0
                0 0.009980039920159682
                0 0
                0.0009980039920159682 0
                0.0009980039920159682 0.009980039920159682
              ]
            }
            coordIndex [
              0, 1, 2, 3, -1, 4, 5, 6, 7, -1, 8, 9, 10, 11, -1, 12, 13, 14, 15, -1, 16, 17, 18, 19, -1, 20, 21, 22, 23, -1
            ]
            creaseAngle 1.5
          }
        }
      ]
      name "wall#3"
      model "box"
      boundingObject Box {
        size 10.02 0.01 0.1
      }
    }
    Solid {
      translation 0 -5.005 0.05
      children [
        Shape {
          appearance PBRAppearance {
            baseColorMap ImageTexture {
              url [
                "https://raw.githubusercontent.com/cyberbotics/webots/R2025a/projects/appearances/protos/textures/brushed_aluminium/brushed_aluminium_base_color.jpg"
              ]
            }
            roughnessMap ImageTexture {
              url [
                "https://raw.githubusercontent.com/cyberbotics/webots/R2025a/projects/appearances/protos/textures/brushed_aluminium/brushed_aluminium_roughness.jpg"
              ]
            }
            normalMap ImageTexture {
              url [
                "https://raw.githubusercontent.com/cyberbotics/webots/R2025a/projects/appearances/protos/textures/brushed_aluminium/brushed_aluminium_normal.jpg"
              ]
            }
          }
          geometry IndexedFaceSet {
            coord Coordinate {
              point [
                -5.01 0.005 0.05
                5.01 0.005 0.05
                5.01 0.005 -0.05
                -5.01 0.005 -0.05
                -5.01 -0.005 -0.05
                5.01 -0.005 -0.05
                5.01 -0.005 0.05
                -5.01 -0.005 0.05
                -5.01 -0.005 0.05
                5.01 -0.005 0.05
                5.01 0.005 0.05
                -5.01 0.005 0.05
                5.01 -0.005 -0.05
                -5.01 -0.005 -0.05
                -5.01 0.005 -0.05
                5.01 0.005 -0.05
                -5.01 -0.005 -0.05
                -5.01 -0.005 0.05
                -5.01 0.005 0.05
                -5.01 0.005 -0.05
                5.01 -0.005 0.05
                5.01 -0.005 -0.05
                5.01 0.005 -0.05
                5.01 0.005 0.05
              ]
            }
            texCoord TextureCoordinate {
              point [
                1 0.009980039920159682
                0 0.009980039920159682
                0 0
                1 0
                0 0
                1 0
                1 0.009980039920159682
                0 0.009980039920159682
                0 1
                0 0
                0.0009980039920159682 0
                0.0009980039920159682 1
                0 1
                0 0
                0.0009980039920159682 0
                0.0009980039920159682 1
                0.0009980039920159682 0
                0.0009980039920159682 0.009980039920159682
                0 0.009980039920159682
                0 0
                0 0.009980039920159682
                0 0
                0.0009980039920159682 0
                0.0009980039920159682 0.009980039920159682
              ]
            }
            coordIndex [
              0, 1, 2, 3, -1, 4, 5, 6, 7, -1, 8, 9, 10, 11, -1, 12, 13, 14, 15, -1, 16, 17, 18, 19, -1, 20, 21, 22, 23, -1
            ]
            creaseAngle 1.5
          }
        }
      ]
      name "wall#4"
      model "box"
      boundingObject Box {
        size 10.02 0.01 0.1
      }
    }
  ]
  name "rectangle arena"
  model "rectangle arena"
  locked TRUE
}
Solid {
  translation 2.55 0.2 0
  rotation 0 0 1 3.14159
  children [
    DEF WALL Shape {
      appearance PBRAppearance {
      }
      geometry Box {
        size 0.5 0.1 0.1
      }
    }
  ]
  name "wall(6)"
  boundingObject USE WALL
}
Solid {
  translation 2.55 1.3 0
  rotation 0 0 1 3.14159
  children [
    DEF WALL Shape {
      appearance PBRAppearance {
      }
      geometry Box {
        size 0.5 0.1 0.1
      }
    }
  ]
  name "wall(11)"
  boundingObject USE WALL
}
Solid {
  translation 3.05 1.3 0
  rotation 0 0 1 3.14159
  children [
    DEF WALL Shape {
      appearance PBRAppearance {
      }
      geometry Box {
        size 0.5 0.1 0.4
      }
    }
  ]
  name "wall(12)"
  boundingObject USE WALL
}
Solid {
  translation 2.67 2.21 0
  rotation 0 0 1 3.14159
  children [
    DEF WALL Shape {
      appearance PBRAppearance {
      }
      geometry Box {
        size 1.3 0.1 0.4
      }
    }
  ]
  name "bigwall"
  boundingObject USE WALL
}
Solid {
  translation 2.67 4.66 0
  rotation 0 0 1 3.14159
  children [
    DEF WALL Shape {
      appearance PBRAppearance {
      }
      geometry Box {
        size 1.3 0.1 0.4
      }
    }
  ]
  name "bigwall(6)"
  boundingObject USE WALL
}
Solid {
  translation 2.27 3.55 0
  rotation 0 0 1 3.14159
  children [
    DEF WALL Shape {
      appearance PBRAppearance {
      }
      geometry Box {
        size 1.3 0.1 0.4
      }
    }
  ]
  name "bigwall(1)"
  boundingObject USE WALL
}
Solid {
  translation 3.92 3.55 0
  rotation 0 0 1 3.14159
  children [
    DEF WALL Shape {
      appearance PBRAppearance {
      }
      geometry Box {
        size 1.3 0.1 0.4
      }
    }
  ]
  name "bigwall(4)"
  boundingObject USE WALL
}
Solid {
  translation 3.31 2.88 0
  rotation 0 0 -1 -1.5707953071795862
  children [
    DEF WALL Shape {
      appearance PBRAppearance {
      }
      geometry Box {
        size 1.3 0.1 0.4
      }
    }
  ]
  name "bigwall(2)"
  boundingObject USE WALL
}
Solid {
  translation 3.31 4.08 0
  rotation 0 0 -1 -1.5707953071795862
  children [
    DEF WALL Shape {
      appearance PBRAppearance {
      }
      geometry Box {
        size 1.3 0.1 0.4
      }
    }
  ]
  name "bigwall(5)"
  boundingObject USE WALL
}
Solid {
  translation 2.05 2.88 0
  rotation 0 0 -1 -1.5707953071795862
  children [
    DEF WALL Shape {
      appearance PBRAppearance {
      }
      geometry Box {
        size 1.3 0.1 0.4
      }
    }
  ]
  name "bigwall(3)"
  boundingObject USE WALL
}
Solid {
  translation 2.05 4.02 0
  rotation 0 0 -1 -1.5707953071795862
  children [
    DEF WALL Shape {
      appearance PBRAppearance {
      }
      geometry Box {
        size 1.3 0.1 0.4
      }
    }
  ]
  name "bigwall(7)"
  boundingObject USE WALL
}
Solid {
  translation 3.3 1.3 0
  rotation 0 0 1 3.14159
  children [
    DEF WALL Shape {
      appearance PBRAppearance {
      }
      geometry Box {
        size 0.5 0.1 0.1
      }
    }
  ]
  name "wall(14)"
  boundingObject USE WALL
}
