#VRML_SIM R2025a utf8

EXTERNPROTO "https://raw.githubusercontent.com/cyberbotics/webots/R2025a/projects/objects/backgrounds/protos/TexturedBackground.proto"
EXTERNPROTO "https://raw.githubusercontent.com/cyberbotics/webots/R2025a/projects/objects/backgrounds/protos/TexturedBackgroundLight.proto"

WorldInfo {
}
Viewpoint {
  orientation -0.4439661291406841 -0.45221356636966176 0.77356122354153 4.4762762863116965
  position 3.1270689591771728 2.4678512581727565 2.4087055891860047
}
TexturedBackground {
}
TexturedBackgroundLight {
}
Robot {
  translation 3.66177 -0.119577 0.039721
  rotation 3.748105583136017e-10 -4.19594838830114e-08 0.9999999999999991 -3.1237305811400824
  children [
    DEF compass Compass {
    }
    DEF BODY Shape {
      appearance PBRAppearance {
        baseColor 0.917647 0.145098 0.145098
        roughness 1
        metalness 0
      }
      geometry Box {
        size 0.2 0.1 0.05
      }
    }
    DEF WHEEL1 HingeJoint {
      jointParameters HingeJointParameters {
        position 69.06016951895451
        axis 0 1 0
        anchor 0.05 0.06 0
      }
      device [
        PositionSensor {
          name "encoder1"
        }
        RotationalMotor {
          name "wheel1"
        }
      ]
      endPoint Solid {
        translation 0.050003442723277766 0.060000001823789756 1.8829861751727665e-06
        rotation -0.35748617171691455 0.6603805764331785 -0.6603795357981407 3.8282536931079543
        children [
          DEF WHEEL Shape {
            appearance PBRAppearance {
              baseColor 0.305882 0.898039 0.25098
              roughness 1
              metalness 0
            }
            geometry Cylinder {
              height 0.02
              radius 0.04
              subdivision 24
            }
          }
        ]
        boundingObject USE WHEEL
        physics Physics {
        }
      }
    }
    DEF WHEEL2 HingeJoint {
      jointParameters HingeJointParameters {
        position 200.52494543240522
        axis 0 1 0
        anchor 0.05 -0.06 0
      }
      device [
        PositionSensor {
          name "encoder2"
        }
        RotationalMotor {
          name "wheel2"
        }
      ]
      endPoint Solid {
        translation 0.050003444772721534 -0.059999998174488686 1.8791261992759618e-06
        rotation 0.7661002272432121 0.4544716297262018 -0.4544732990967776 1.8341444461245677
        children [
          USE WHEEL
        ]
        name "solid(1)"
        boundingObject USE WHEEL
        physics Physics {
        }
      }
    }
    DEF WHEEL3 HingeJoint {
      jointParameters HingeJointParameters {
        position 69.0601988498348
        axis 0 1 0
        anchor -0.05 0.06 0
      }
      device [
        RotationalMotor {
          name "wheel3"
        }
      ]
      endPoint Solid {
        translation -0.04999655729311627 0.05999999817434007 1.883016582259933e-06
        rotation 0.9992486299568606 -0.02740593063252714 0.027406030276236712 1.5715516586143994
        children [
          USE WHEEL
        ]
        name "solid(2)"
        boundingObject USE WHEEL
        physics Physics {
        }
      }
    }
    DEF WHEEL4 HingeJoint {
      jointParameters HingeJointParameters {
        position 200.5249752390411
        axis 0 1 0
        anchor -0.05 -0.06 0
      }
      device [
        RotationalMotor {
          name "wheel4"
        }
      ]
      endPoint Solid {
        translation -0.049996555243671865 -0.060000001823938484 1.87915660517568e-06
        rotation 0.9319454403761752 -0.2563954118420311 0.25639635127749416 1.641222722175188
        children [
          USE WHEEL
        ]
        name "solid(3)"
        boundingObject USE WHEEL
        physics Physics {
        }
      }
    }
    DEF DS_RIGHT DistanceSensor {
      translation 0.1 -0.03 0
      rotation 0 0 1 -0.3
      children [
        Shape {
          appearance PBRAppearance {
            baseColor 0.184314 0.596078 0.847059
            roughness 1
            metalness 0
          }
          geometry Box {
            size 0.01 0.01 0.01
          }
        }
      ]
      name "ds_right"
    }
    DEF DS_LEFT DistanceSensor {
      translation 0.1 0.03 0
      rotation 0 0 1 0.3
      children [
        Shape {
          appearance PBRAppearance {
            baseColor 0.184314 0.596078 0.847059
            roughness 1
            metalness 0
          }
          geometry Box {
            size 0.01 0.01 0.01
          }
        }
      ]
      name "ds_left"
    }
  ]
  boundingObject USE BODY
  physics Physics {
    density -1
    mass 1
  }
  controller "robotcar"
}
Solid {
  translation 3.3 0.05 0
  children [
    DEF WALL Shape {
      appearance PBRAppearance {
      }
      geometry Box {
        size 0.5 0.1 0.1
      }
    }
  ]
  name "wall"
  boundingObject USE WALL
}
Solid {
  translation 3.1 0.25 0
  rotation 0 0 1 -1.5707953071795862
  children [
    DEF WALL Shape {
      appearance PBRAppearance {
      }
      geometry Box {
        size 0.5 0.1 0.1
      }
    }
  ]
  name "wall(1)"
  boundingObject USE WALL
}
Solid {
  translation 2.25 0.5 0
  rotation 0 0 1 -1.5707953071795862
  children [
    DEF WALL Shape {
      appearance PBRAppearance {
      }
      geometry Box {
        size 0.5 0.1 0.1
      }
    }
  ]
  name "wall(7)"
  boundingObject USE WALL
}
Solid {
  translation 2.25 1 0
  rotation 0 0 1 -1.5707953071795862
  children [
    DEF WALL Shape {
      appearance PBRAppearance {
      }
      geometry Box {
        size 0.5 0.1 0.1
      }
    }
  ]
  name "wall(10)"
  boundingObject USE WALL
}
Solid {
  translation 2.59 0.75 0
  rotation 0 0 1 -1.5707953071795862
  children [
    DEF WALL Shape {
      appearance PBRAppearance {
      }
      geometry Box {
        size 0.5 0.1 0.1
      }
    }
  ]
  name "wall(8)"
  boundingObject USE WALL
}
Solid {
  translation 3.3 -0.3 0
  rotation 0 0 1 3.14159
  children [
    DEF WALL Shape {
      appearance PBRAppearance {
      }
      geometry Box {
        size 0.5 0.1 0.1
      }
    }
  ]
  name "wall(2)"
  boundingObject USE WALL
}
Solid {
  translation 2.8 0.55 0
  rotation 0 0 1 3.14159
  children [
    DEF WALL Shape {
      appearance PBRAppearance {
      }
      geometry Box {
        size 0.5 0.1 0.1
      }
    }
  ]
  name "wall(3)"
  boundingObject USE WALL
}
Solid {
  translation 2.8 0.95 0
  rotation 0 0 1 3.14159
  children [
    DEF WALL Shape {
      appearance PBRAppearance {
      }
      geometry Box {
        size 0.5 0.1 0.1
      }
    }
  ]
  name "wall(9)"
  boundingObject USE WALL
}
Solid {
  translation 3.3 0.95 0
  rotation 0 0 1 3.14159
  children [
    DEF WALL Shape {
      appearance PBRAppearance {
      }
      geometry Box {
        size 0.5 0.1 0.1
      }
    }
  ]
  name "wall(13)"
  boundingObject USE WALL
}
Solid {
  translation 2.8 -0.3 0
  rotation 0 0 1 3.14159
  children [
    DEF WALL Shape {
      appearance PBRAppearance {
      }
      geometry Box {
        size 0.5 0.1 0.1
      }
    }
  ]
  name "wall(4)"
  boundingObject USE WALL
}
Solid {
  translation 2.75 -5.0981e-08 0
  rotation 0 0 1 -1.5707953071795862
  children [
    DEF WALL Shape {
      appearance PBRAppearance {
      }
      geometry Box {
        size 0.5 0.1 0.1
      }
    }
  ]
  name "wall(5)"
  boundingObject USE WALL
}
Solid {
  translation 3.55 0 0
  children [
    Solid {
      children [
        Shape {
          appearance PBRAppearance {
            baseColorMap ImageTexture {
              url [
                "https://raw.githubusercontent.com/cyberbotics/webots/R2025a/projects/appearances/protos/textures/parquetry/chequered_parquetry_base_color.jpg"
              ]
            }
            roughness 1
            roughnessMap ImageTexture {
              url [
                "https://raw.githubusercontent.com/cyberbotics/webots/R2025a/projects/appearances/protos/textures/parquetry/chequered_parquetry_roughness.jpg"
              ]
            }
            metalness 0
            normalMap ImageTexture {
              url [
                "https://raw.githubusercontent.com/cyberbotics/webots/R2025a/projects/appearances/protos/textures/parquetry/chequered_parquetry_normal.jpg"
              ]
            }
            occlusionMap ImageTexture {
              url [
                "https://raw.githubusercontent.com/cyberbotics/webots/R2025a/projects/appearances/protos/textures/parquetry/chequered_parquetry_occlusion.jpg"
              ]
            }
          }
          geometry IndexedFaceSet {
            coord Coordinate {
              point [
                -5 -5 0
                5 -5 0
                -5 5 0
                5 5 0
              ]
            }
            texCoord TextureCoordinate {
              point [
                0 0
                20 0
                0 20
                20 20
              ]
            }
            coordIndex [
              2, 0, 1, 3, -1
            ]
            texCoordIndex [
              2, 0, 1, 3, -1
            ]
          }
        }
      ]
      name "floor"
      model "floor"
      boundingObject Plane {
        size 10 10
      }
      locked TRUE
    }
    Solid {
      translation 5.005 0 0.05
      children [
        Shape {
          appearance PBRAppearance {
            baseColorMap ImageTexture {
              url [
                "https://raw.githubusercontent.com/cyberbotics/webots/R2025a/projects/appearances/protos/textures/brushed_aluminium/brushed_aluminium_base_color.jpg"
              ]
            }
            roughnessMap ImageTexture {
              url [
                "https://raw.githubusercontent.com/cyberbotics/webots/R2025a/projects/appearances/protos/textures/brushed_aluminium/brushed_aluminium_roughness.jpg"
              ]
            }
            normalMap ImageTexture {
              url [
                "https://raw.githubusercontent.com/cyberbotics/webots/R2025a/projects/appearances/protos/textures/brushed_aluminium/brushed_aluminium_normal.jpg"
              ]
            }
          }
          geometry IndexedFaceSet {
            coord Coordinate {
              point [
                -0.005 5 0.05
                0.005 5 0.05
                0.005 5 -0.05
                -0.005 5 -0.05
                -0.005 -5 -0.05
                0.005 -5 -0.05
                0.005 -5 0.05
                -0.005 -5 0.05
                -0.005 -5 0.05
                0.005 -5 0.05
                0.005 5 0.05
                -0.005 5 0.05
                0.005 -5 -0.05
                -0.005 -5 -0.05
                -0.005 5 -0.05
                0.005 5 -0.05
                -0.005 -5 -0.05
                -0.005 -5 0.05
                -0.005 5 0.05
                -0.005 5 -0.05
                0.005 -5 0.05
                0.005 -5 -0.05
                0.005 5 -0.05
                0.005 5 0.05
              ]
            }
            texCoord TextureCoordinate {
              point [
                0.001 0.01
                0 0.01
                0 0
                0.001 0
                0 0
                0.001 0
                0.001 0.01
                0 0.01
                0 0.001
                0 0
                1 0
                1 0.001
                0 0.001
                0 0
                1 0
                1 0.001
                1 0
                1 0.01
                0 0.01
                0 0
                0 0.01
                0 0
                1 0
                1 0.01
              ]
            }
            coordIndex [
              0, 1, 2, 3, -1, 4, 5, 6, 7, -1, 8, 9, 10, 11, -1, 12, 13, 14, 15, -1, 16, 17, 18, 19, -1, 20, 21, 22, 23, -1
            ]
            creaseAngle 1.5
          }
        }
      ]
      name "wall"
      model "box"
      boundingObject Box {
        size 0.01 10 0.1
      }
    }
    Solid {
      translation -5.005 0 0.05
      children [
        Shape {
          appearance PBRAppearance {
            baseColorMap ImageTexture {
              url [
                "https://raw.githubusercontent.com/cyberbotics/webots/R2025a/projects/appearances/protos/textures/brushed_aluminium/brushed_aluminium_base_color.jpg"
              ]
            }
            roughnessMap ImageTexture {
              url [
                "https://raw.githubusercontent.com/cyberbotics/webots/R2025a/projects/appearances/protos/textures/brushed_aluminium/brushed_aluminium_roughness.jpg"
              ]
            }
            normalMap ImageTexture {
              url [
                "https://raw.githubusercontent.com/cyberbotics/webots/R2025a/projects/appearances/protos/textures/brushed_aluminium/brushed_aluminium_normal.jpg"
              ]
            }
          }
          geometry IndexedFaceSet {
            coord Coordinate {
              point [
                -0.005 5 0.05
                0.005 5 0.05
                0.005 5 -0.05
                -0.005 5 -0.05
                -0.005 -5 -0.05
                0.005 -5 -0.05
                0.005 -5 0.05
                -0.005 -5 0.05
                -0.005 -5 0.05
                0.005 -5 0.05
                0.005 5 0.05
                -0.005 5 0.05
                0.005 -5 -0.05
                -0.005 -5 -0.05
                -0.005 5 -0.05
                0.005 5 -0.05
                -0.005 -5 -0.05
                -0.005 -5 0.05
                -0.005 5 0.05
                -0.005 5 -0.05
                0.005 -5 0.05
                0.005 -5 -0.05
                0.005 5 -0.05
                0.005 5 0.05
              ]
            }
            texCoord TextureCoordinate {
              point [
                0.001 0.01
                0 0.01
                0 0
                0.001 0
                0 0
                0.001 0
                0.001 0.01
                0 0.01
                0 0.001
                0 0
                1 0
                1 0.001
                0 0.001
                0 0
                1 0
                1 0.001
                1 0
                1 0.01
                0 0.01
                0 0
                0 0.01
                0 0
                1 0
                1 0.01
              ]
            }
            coordIndex [
              0, 1, 2, 3, -1, 4, 5, 6, 7, -1, 8, 9, 10, 11, -1, 12, 13, 14, 15, -1, 16, 17, 18, 19, -1, 20, 21, 22, 23, -1
            ]
            creaseAngle 1.5
          }
        }
      ]
      name "wall#2"
      model "box"
      boundingObject Box {
        size 0.01 10 0.1
      }
    }
    Solid {
      translation 0 5.005 0.05
      children [
        Shape {
          appearance PBRAppearance {
            baseColorMap ImageTexture {
              url [
                "https://raw.githubusercontent.com/cyberbotics/webots/R2025a/projects/appearances/protos/textures/brushed_aluminium/brushed_aluminium_base_color.jpg"
              ]
            }
            roughnessMap ImageTexture {
              url [
                "https://raw.githubusercontent.com/cyberbotics/webots/R2025a/projects/appearances/protos/textures/brushed_aluminium/brushed_aluminium_roughness.jpg"
              ]
            }
            normalMap ImageTexture {
              url [
                "https://raw.githubusercontent.com/cyberbotics/webots/R2025a/projects/appearances/protos/textures/brushed_aluminium/brushed_aluminium_normal.jpg"
              ]
            }
          }
          geometry IndexedFaceSet {
            coord Coordinate {
              point [
                -5.01 0.005 0.05
                5.01 0.005 0.05
                5.01 0.005 -0.05
                -5.01 0.005 -0.05
                -5.01 -0.005 -0.05
                5.01 -0.005 -0.05
                5.01 -0.005 0.05
                -5.01 -0.005 0.05
                -5.01 -0.005 0.05
                5.01 -0.005 0.05
                5.01 0.005 0.05
                -5.01 0.005 0.05
                5.01 -0.005 -0.05
                -5.01 -0.005 -0.05
                -5.01 0.005 -0.05
                5.01 0.005 -0.05
                -5.01 -0.005 -0.05
                -5.01 -0.005 0.05
                -5.01 0.005 0.05
                -5.01 0.005 -0.05
                5.01 -0.005 0.05
                5.01 -0.005 -0.05
                5.01 0.005 -0.05
                5.01 0.005 0.05
              ]
            }
            texCoord TextureCoordinate {
              point [
                1 0.009980039920159682
                0 0.009980039920159682
                0 0
                1 0
                0 0
                1 0
                1 0.009980039920159682
                0 0.009980039920159682
                0 1
                0 0
                0.0009980039920159682 0
                0.0009980039920159682 1
                0 1
                0 0
                0.0009980039920159682 0
                0.0009980039920159682 1
                0.0009980039920159682 0
                0.0009980039920159682 0.009980039920159682
                0 0.009980039920159682
                0 0
                0 0.009980039920159682
                0 0
                0.0009980039920159682 0
                0.0009980039920159682 0.009980039920159682
              ]
            }
            coordIndex [
              0, 1, 2, 3, -1, 4, 5, 6, 7, -1, 8, 9, 10, 11, -1, 12, 13, 14, 15, -1, 16, 17, 18, 19, -1, 20, 21, 22, 23, -1
            ]
            creaseAngle 1.5
          }
        }
      ]
      name "wall#3"
      model "box"
      boundingObject Box {
        size 10.02 0.01 0.1
      }
    }
    Solid {
      translation 0 -5.005 0.05
      children [
        Shape {
          appearance PBRAppearance {
            baseColorMap ImageTexture {
              url [
                "https://raw.githubusercontent.com/cyberbotics/webots/R2025a/projects/appearances/protos/textures/brushed_aluminium/brushed_aluminium_base_color.jpg"
              ]
            }
            roughnessMap ImageTexture {
              url [
                "https://raw.githubusercontent.com/cyberbotics/webots/R2025a/projects/appearances/protos/textures/brushed_aluminium/brushed_aluminium_roughness.jpg"
              ]
            }
            normalMap ImageTexture {
              url [
                "https://raw.githubusercontent.com/cyberbotics/webots/R2025a/projects/appearances/protos/textures/brushed_aluminium/brushed_aluminium_normal.jpg"
              ]
            }
          }
          geometry IndexedFaceSet {
            coord Coordinate {
              point [
                -5.01 0.005 0.05
                5.01 0.005 0.05
                5.01 0.005 -0.05
                -5.01 0.005 -0.05
                -5.01 -0.005 -0.05
                5.01 -0.005 -0.05
                5.01 -0.005 0.05
                -5.01 -0.005 0.05
                -5.01 -0.005 0.05
                5.01 -0.005 0.05
                5.01 0.005 0.05
                -5.01 0.005 0.05
                5.01 -0.005 -0.05
                -5.01 -0.005 -0.05
                -5.01 0.005 -0.05
                5.01 0.005 -0.05
                -5.01 -0.005 -0.05
                -5.01 -0.005 0.05
                -5.01 0.005 0.05
                -5.01 0.005 -0.05
                5.01 -0.005 0.05
                5.01 -0.005 -0.05
                5.01 0.005 -0.05
                5.01 0.005 0.05
              ]
            }
            texCoord TextureCoordinate {
              point [
                1 0.009980039920159682
                0 0.009980039920159682
                0 0
                1 0
                0 0
                1 0
                1 0.009980039920159682
                0 0.009980039920159682
                0 1
                0 0
                0.0009980039920159682 0
                0.0009980039920159682 1
                0 1
                0 0
                0.0009980039920159682 0
                0.0009980039920159682 1
                0.0009980039920159682 0
                0.0009980039920159682 0.009980039920159682
                0 0.009980039920159682
                0 0
                0 0.009980039920159682
                0 0
                0.0009980039920159682 0
                0.0009980039920159682 0.009980039920159682
              ]
            }
            coordIndex [
              0, 1, 2, 3, -1, 4, 5, 6, 7, -1, 8, 9, 10, 11, -1, 12, 13, 14, 15, -1, 16, 17, 18, 19, -1, 20, 21, 22, 23, -1
            ]
            creaseAngle 1.5
          }
        }
      ]
      name "wall#4"
      model "box"
      boundingObject Box {
        size 10.02 0.01 0.1
      }
    }
  ]
  name "rectangle arena"
  model "rectangle arena"
  locked TRUE
}
Solid {
  translation 2.55 0.2 0
  rotation 0 0 1 3.14159
  children [
    DEF WALL Shape {
      appearance PBRAppearance {
      }
      geometry Box {
        size 0.5 0.1 0.1
      }
    }
  ]
  name "wall(6)"
  boundingObject USE WALL
}
Solid {
  translation 2.55 1.3 0
  rotation 0 0 1 3.14159
  children [
    DEF WALL Shape {
      appearance PBRAppearance {
      }
      geometry Box {
        size 0.5 0.1 0.1
      }
    }
  ]
  name "wall(11)"
  boundingObject USE WALL
}
Solid {
  translation 3.05 1.3 0
  rotation 0 0 1 3.14159
  children [
    DEF WALL Shape {
      appearance PBRAppearance {
      }
      geometry Box {
        size 0.5 0.1 0.1
      }
    }
  ]
  name "wall(12)"
  boundingObject USE WALL
}
Solid {
  translation 3.3 1.3 0
  rotation 0 0 1 3.14159
  children [
    DEF WALL Shape {
      appearance PBRAppearance {
      }
      geometry Box {
        size 0.5 0.1 0.1
      }
    }
  ]
  name "wall(14)"
  boundingObject USE WALL
}
